Workbook
Name EXECUTIONSTRATEGY: #REF!
Name EXECUTIONSTRATEGY: #REF!
Name EXECUTIONSTRATEGY: #REF!
Name Labor: 'Drop Down Data'!$A$12
Name Month: #REF!
Name Month: #REF!
Name Month: #REF!
Name NumWorkItems: [1]BGCalcs!$J$14
Name OverflowWeight: [2]BGCalcs!$K$24
Name percentabovemedian: [2]BGCalcs!$K$26
Name PrimeWeight: [2]BGCalcs!$K$23
Name ProbationalSwitch: [2]BGCalcs!$K$22
Name Regions: #REF!
Name Regions: #REF!
Name Regions: #REF!
Name Resource: [3]Resources!$C$6:$C$13
Name Scenarios: [2]BGCalcs!$B$3:$B$7
Name Scenarios2: [2]BGCalcs!$B$10:$B$14
Name Supp1Weight: [2]BGCalcs!$H$22
Name Supp2Weight: [2]BGCalcs!$H$24
Name Suppliers: [1]BGCalcs!$C$14:$C$109
Name SuppliersOrig: [4]PasteHere!$E$4:$BJ$4
Name Territories: [2]Num1Supplier!$B$5:$B$34
Name TerritoriesHoriz: [2]BGCalcs!$C$2:$AF$2
Name TerritoriesHoriz2nd: [2]BGCalcs!$C$9:$AF$9
Name TotalSpend: [2]BGCalcs!$H$18
Name VendByRegAndScen: [2]BGCalcs!$C$3:$AF$7
Name VendByRegAndScen2nd: [2]BGCalcs!$C$10:$AF$14
Name Verticals: #REF!
Name Verticals: #REF!
Name Verticals: #REF!
Name WorkAuth: [2]BGCalcs!$H$20
Name WorkItems: [1]BGCalcs!$I$14:$I$314

Sheet Cover Sheet
A1: Estimate Package For:
A9: Client
A10: Project
A11: RFP Received Date | F11: Bid Due Date
A12: Estimated By
A13: Customer Contact Name | F13: Phone | I13: Email
A15: Customer Type | C15: Direct Customer | F15: General Contractor | I15: Sub/Tier
A16: Job Site Address
A18: Project Overview
A24: Project Specifics- Previous Customer Experiences, Special Circumstances etc

Sheet Executive Summary
B1: Mark-Ups Applied | I1: Break-Even
B2: Denotes Fields for Input | E2: Denotes DO NOT TOUCH | I2: Denotes Fields for Input | L2: Denotes DO NOT TOUCH
B3: Description | C3: Amount | D3: Totals | E3: Hours | F3: M/U Rate | G3: Fed From | I3: Description | J3: Amount | K3: Totals | L3: Hours | M3: M/U Rate | N3: Fed From
B4: Labor | I4: Labor
B5: Operational Labor | C5: ='Labor Projections'!G9 -> 0 | D5: =C5*F8+C5 -> 0 | E5: ='Labor Projections'!F9 -> 0 | G5: Labor Projections | I5: Operational Labor | J5: ='Labor Projections'!G9 -> 0 | L5: ='Labor Projections'!F9 -> 0 | N5: Labor Projections
B6: Ops Admin Labor | C6: ='Labor Projections'!G14 -> 0 | D6: =C6*F8+C6 -> 0 | E6: ='Labor Projections'!F14 -> 0 | G6: Labor Projections | I6: Ops Admin Labor | J6: ='Labor Projections'!G14 -> 0 | L6: ='Labor Projections'!F14 -> 0 | N6: Labor Projections
B7: Travel | C7: ='Pass Throughs'!E31 -> 0 | D7: =C7*F8+C7 -> 0 | E7: ='Pass Throughs'!F31 -> 0 | I7: Travel | J7: ='Pass Throughs'!E31 -> 0 | L7: ='Pass Throughs'!F31 -> 0
B8: Total Project Labor | D8: =SUM(C5:C7)*F8+SUM(C5:C7) -> 0 | E8: =SUM(E5:E7) -> 0 | F8: 0.25 | H8: =D8-K8 -> 0 | I8: Total Project Labor | K8: =SUM(J5:J7) -> 0 | L8: =SUM(L5:L6) -> 0 | M8: 0
B9: Pass Through | I9: Pass Through
B10: Per Diem | C10: ='Pass Throughs'!E11 -> 0 | D10: =C10*F15+C10 -> 0 | G10: Pass Throughs | I10: Per Diem | J10: ='Pass Throughs'!E11 -> 0 | N10: Pass Throughs
B11: Lodging | C11: ='Pass Throughs'!E21 -> 0 | D11: =C11*F15+C11 -> 0 | G11: Pass Throughs | I11: Lodging | J11: ='Pass Throughs'!E21 -> 0 | N11: Pass Throughs
B12: Airfare | C12: ='Pass Throughs'!E41 -> 0 | D12: =C12*F15+C12 -> 0 | G12: Pass Throughs | I12: Airfare | J12: ='Pass Throughs'!E41 -> 0 | N12: Pass Throughs
B13: Rentals | C13: ='Pass Throughs'!E58 -> 0 | D13: =C13*F15+C13 -> 0 | G13: Pass Throughs | I13: Rentals | J13: ='Pass Throughs'!E58 -> 0 | N13: Pass Throughs
B14: Soft Costs | C14: ='Pass Throughs'!E72 -> 0 | D14: =C14*F59+C14 -> 0 | G14: Pass Throughs | I14: Soft Costs | J14: ='Pass Throughs'!E72 -> 0 | N14: Pass Throughs
B15: Total Pass Through Expense | D15: =SUM(C10:C14)*F15+SUM(C10:C14) -> 0 | E15: =SUM(E10:E14) -> 0 | F15: 0.25 | H15: =D15-K15 -> 0 | I15: Total Pass Through Expense | K15: =SUM(J10:J14) -> 0 | L15: =SUM(L10:L14) -> 0 | M15: 0
B16: Material | I16: Material
B17: Consumable | C17: ='Bill of Materials'!I87 -> 0 | D17: =C17*F21+C17 -> 0 | G17: Bill of Materials | I17: Consumable | J17: ='Bill of Materials'!I87 -> 0 | N17: Bill of Materials
B18: DAS Materials | C18: ='Bill of Materials'!I88 -> 0 | D18: =C18*F21+C18 -> 0 | G18: Bill of Materials | I18: DAS Materials | J18: ='Bill of Materials'!I88 -> 0 | N18: Bill of Materials
B19: BAT Materials | C19: ='Bill of Materials'!I89 -> 0 | D19: =C19*F21+C19 -> 0 | G19: Bill of Materials | I19: BAT Materials | J19: ='Bill of Materials'!I89 -> 0 | N19: Bill of Materials
B20: S&H / Material Contingency | C20: ='Bill of Materials'!I90+'Bill of Materials'!I91 -> 0 | D20: =C20*F21+C20 -> 0 | I20: S&H / Material Contingency | J20: ='Bill of Materials'!I90+'Bill of Materials'!I91 -> 0
B21: Total Materials | D21: =((C17+C18+C19+C20)*F21)+C17+C18+C19+C20 -> 0 | F21: 0.25 | H21: =D21-K21 -> 0 | I21: Total Materials | K21: =SUM(J17:J20) -> 0 | M21: 0
B22: Projected Gross Margins Grand Totals | I22: Projected Gross Margins Grand Totals
B23: Total Direct Cost | D23: =D8+D15+D21 -> 0 | H23: =D23-K23 -> 0 | I23: Total Direct Cost | K23: =K8+K15+K21 -> 0
B24: Projected Gross Profit $$ | C24: =D23-K23 -> 0 | D24: =D23 -> 0 | I24: Projected Gross Profit $$ | J24: =K23-K32 -> 0 | K24: =K23 -> 0
B25: Mark-Up% | C25: =IF(D23,(D23/K23)-1,0) -> 0 | I25: Mark-Up% | J25: =IF(K23,(K23/K23)-1,0) -> 0
B26: Gross Margin % | C26: =IF(D23,1-(K23/D23),0) -> 0 | I26: Gross Margin % | J26: =IF(K23,1-(K23/K23),0) -> 0
B27: Tweak for Margin Target | I27: Tweak for Margin Target
B28: Tweak for Margin Target | G28: To achieve desired GM | I28: Tweak for Margin Target | J28: 0 | K28: =K24+J28 -> 0
B29: PGM $$ Post Tweak | C29: =C24+C28 -> 0 | D29: =C28+D24 -> 0 | I29: PGM $$ Post Tweak | J29: =J24+J28 -> 0 | K29: =J28+K28 -> 0
B30: Mark-Up% Post Tweak | C30: =IF(D23,(D32/K32)-1,0) -> 0 | I30: Mark-Up% Post Tweak | J30: =IF(K23,(K32/K32)-1,0) -> 0
B31: Gross Margin % Post Tweak | C31: =IF(D23,1-(K32/D29),0) -> 0 | I31: Gross Margin % Post Tweak | J31: =IF(K23,1-(K32/K32),0) -> 0
B32: PGM Grand Total | D32: =D29 -> 0 | H32: =D32-K32 -> 0 | I32: Grand Total | K32: =K29 -> 0
B33: Projected Net Margins Grand Totals | I33: Projected Net Margins Grand Totals
B34: Mark-Up for Corporate | C34: =D32*F35 -> 0 | H34: =C34-J34 -> 0 | I34: Cost of Corporate | J34: =K32*M35 -> 0
B35: PNM Grand Total | D35: =D32+C34 -> 0 | F35: 0.05 | I35: PNM Grand Total | K35: =K29+J34 -> 0
B36: Projected Net Profit $$ | C36: =D32-K35 -> 0 | D36: =D35 -> 0 | H36: =D36-K36 -> 0 | I36: Projected Net Profit $$ | J36: =K32-K35 -> 0 | K36: =J35+K35 -> 0
B37: Mark-Up% | C37: =IF(D35,(D35/K35)-1,0) -> 0 | I37: Mark-Up% | J37: =IF(K32,(K39/K39)-1,0) -> 0
B38: Net Margin % | C38: =IF(D35,1-(K35/D35),0) -> 0 | G38: Higher than GM due to Comm and Corp mark-ups | I38: Net Margin % | J38: =IF(K32,1-(K39/K39),0) -> 0
B39: PNM Grand Total | D39: =D36 -> 0 | H39: =D39-K39 -> 0 | I39: PNM Grand Total | K39: =K36 -> 0
B41: Mark-Ups Applied
...

Sheet Bill of Materials
A1: Denotes Fields for Input | D1: Denotes DO NOT TOUCH | H1: Total from Here | I1: =I92 -> 0
A2: Type | B2: Manufacturer | C2: Model | D2: Item Description | E2: Quantity | F2: Vendor | G2: Category | H2: Unit Cost | I2: Ext Cost | J2: % of Total Cost
A3: DC Power Plant | B3: Vertiv | C3: 582137200 | D3: NetSure 5100 Integrated Power System | F3: Anixter | G3: DAS Materials | H3: 4685 | I3: =H3*E3 -> 0 | J3: =IF(I3=0,0,I3/I$1) -> 0
A4: DC Power Plant | B4: Westell | C4: NPGMT1012 | D4: 100 Amp, Dual Bus, 20A GMT Fuse Panels, 1 RU 19" or 23" rack mount, UL 60950-1 | F4: Anixter | G4: DAS Materials | H4: 360 | I4: =H4*E4 -> 0 | J4: =IF(I4=0,0,I4/I$1) -> 0
A5: DC Power Plant | B5: Cooper Bussmann | C5: BK/GMT-10A | D5: Fuse, GMT, 10 AMP/ 10 pack | F5: Anixter | G5: DAS Materials | H5: 35 | I5: =H5*E5 -> 0 | J5: =IF(I5=0,0,I5/I$1) -> 0
A6: Filter | B6: Microlab/FXR | C6: BK-3001E | D6: Triplexer, PCS/AWS1-3/2.5 BRS, 1850-2000/1695-1780 & 2110-2200/2496-2690 MHz, 100W, 4.3-10 Connectors, Low PIM <-161dBc, IP67 | F6: Anixter | G6: DAS Materials | H6: 1160 | I6: =H6*E6 -> 0 | J6: =IF(I6=0,0,I6/I$1) -> 0
A7: Filter | B7: Advanced RF Technologies | C7: ADXV-R-CHC-U | D7: ADXV: Low PIM Universal Channel Combiner | F7: Anixter | G7: DAS Materials | H7: 1350 | I7: =H7*E7 -> 0 | J7: =IF(I7=0,0,I7/I$1) -> 0
A8: Network Equipment | B8: Advanced RF Technologies | C8: SDR-NMS | D8: [SDR]-NMS; SDR Network Management System w/ Chassis- Support SDR-24/30/33 modules. | F8: Anixter | G8: DAS Materials | H8: 1000 | I8: =H8*E8 -> 0 | J8: =IF(I8=0,0,I8/I$1) -> 0
A9: Antenna | B9: Advanced RF Technologies | C9: AD-PA-1695-4200-D | D9: High-Isolation Donor Antenna / 1695 MHz - 4200 MHz / 17.8 - 19.6 dBi / 20.6 - 13.4 degree beam | F9: Anixter | G9: DAS Materials | H9: 840 | I9: =H9*E9 -> 0 | J9: =IF(I9=0,0,I9/I$1) -> 0
A10: Antenna | B10: JMA Wireless | C10: iV02OMI136-M4 | D10: Surface Mount Omni MIMO Antenna, 617-5925 MHz 4.3-10 with pigtails. Use port 2 for SISO systems. | F10: Anixter | G10: DAS Materials | H10: 192 | I10: =H10*E10 -> 0 | J10: =IF(I10=0,0,I10/I$1) -> 0
A11: Antenna | B11: CommScope | C11: CMAX-DMF2-43-WI53 | D11: Low PIM Directional MIMO Antenna 4G/5G/C-Band, 698–960 MHz,1695–2700 MHz and 3300-4200MHz | F11: Anixter | G11: DAS Materials | H11: 344 | I11: =H11*E11 -> 0 | J11: =IF(I11=0,0,I11/I$1) -> 0
A12: Coax Jumpers | B12: RFI | D12: SMA Male to N Male Cable Using LMR-200 Coax - 15' | F12: Anixter | G12: DAS Materials | H12: 42 | I12: =H12*E12 -> 0 | J12: =IF(I12=0,0,I12/I$1) -> 0
A13: Coax Jumpers | B13: RFI | D13: SMA Male Right Angle to N Male Cable Using LMR-200 Coax - 15' | F13: Anixter | G13: DAS Materials | H13: 42 | I13: =H13*E13 -> 0 | J13: =IF(I13=0,0,I13/I$1) -> 0
A14: Coax Jumpers | B14: Times Microwave Systems | C14: SPF25043M43M3.0F | D14: 3ft - 50 Ohm Low Loss, Low PIM Fire Retardant Coaxial Jumper Cable | F14: Anixter | G14: DAS Materials | H14: 29.81 | I14: =H14*E14 -> 0 | J14: =IF(I14=0,0,I14/I$1) -> 0
A15: Combiner | B15: SYM Technology | C15: HC-33-60 | D15: Hybrid combiner 3x3 4.3-10 | F15: Anixter | G15: DAS Materials | H15: 1900 | I15: =H15*E15 -> 0 | J15: =IF(I15=0,0,I15/I$1) -> 0
A16: Combiner | B16: Microlab | C16: CM-680E | D16: Hybrid combiner 3x3 4.3-10 | F16: Anixter | G16: DAS Materials | H16: 964.22 | I16: =H16*E16 -> 0 | J16: =IF(I16=0,0,I16/I$1) -> 0
A17: Combiner | B17: MicroLab | C17: BL-51N | D17: Duplexer AWS 2110-2180/1695-17 80MHz 60W -161dBc N-type IP67 | F17: Anixter | G17: DAS Materials | H17: 1087.89 | I17: =H17*E17 -> 0 | J17: =IF(I17=0,0,I17/I$1) -> 0
A18: Combiner | B18: MicroLab | C18: BL-19N | D18: Duplexer PCS 1850-1915/1930-19 95MHz 60W -153dBc N-type IP64 | F18: Anixter | G18: DAS Materials | H18: 640 | I18: =H18*E18 -> 0 | J18: =IF(I18=0,0,I18/I$1) -> 0
A19: Combiner | B19: MicroLab | C19: CA-84N | D19: Microlab CA-84N 700-2700 MHz Hybrid Coupler N (CA-84N) | F19: Anixter | G19: DAS Materials | H19: 450 | I19: =H19*E19 -> 0 | J19: =IF(I19=0,0,I19/I$1) -> 0
A20: Load | B20: CommScope | C20: T-10-UW-43-M | D20: Termination Load, 0–6000 MHz, Not for PIM-rated applications | F20: Anixter | G20: DAS Materials | H20: 50 | I20: =H20*E20 -> 0 | J20: =IF(I20=0,0,I20/I$1) -> 0
A21: Splitter | B21: Corning | C21: 37G00189332-400F | D21: Corning ONE Composite Cable Assembly, 6F/6C 16 AWG,400 Ft. | F21: Anixter | G21: DAS Materials | H21: 400 | I21: =H21*E21 -> 0 | J21: =IF(I21=0,0,I21/I$1) -> 0
A22: Splitter | B22: Microlab/FXR | C22: DN-54FE | D22: Unequal Power Splitter (Tapper), Low PIM <-161 dBc, 4:1 (6 dB), 350-5930 MHz, 500W, 4.3-10 Connectors, IP67, | F22: Anixter | G22: DAS Materials | H22: 128 | I22: =H22*E22 -> 0 | J22: =IF(I22=0,0,I22/I$1) -> 0
A23: Splitter | B23: Microlab/FXR | C23: DN-34FE | D23: Unequal Power Splitter (Tapper), Low PIM <-161 dBc, 2:1 (3 dB), 350-5930 MHz, 500W, 4.3-10 Connectors IP67 | F23: Anixter | G23: DAS Materials | H23: 119 | I23: =H23*E23 -> 0 | J23: =IF(I23=0,0,I23/I$1) -> 0
A24: Splitter | B24: Microlab/FXR | C24: D2-83FE | D24: 2-way Tube Style - Reactive Power Divider - Ultra Wideband 617-5925 MHz - 300W - Low PIM <-165 dBc - 4.3-10 Connectors, IP67 | F24: Anixter | G24: DAS Materials | H24: 125 | I24: =H24*E24 -> 0 | J24: =IF(I24=0,0,I24/I$1) -> 0
A25: Splitter | B25: Microlab/FXR | C25: DN-84FE | D25: Unequal Power Splitter (Tapper), Low PIM <-161 dBc, 20:1 (13 dB), 350-5930 MHz, 500W, 4.3-10 Connectors, IP67 | F25: Anixter | G25: DAS Materials | H25: 94 | I25: =H25*E25 -> 0 | J25: =IF(I25=0,0,I25/I$1) -> 0
... A40: GPS | B40: Thor | C40: F-1GPS-TX/RX | D40: GPS over Fiber receiver | F40: Thor | G40: DAS Materials | H40: 1495 | I40: =H40*E40 -> 0 | J40: =IF(I40=0,0,I40/I$1) -> 0
A41: GPS | C41: TAPE-SF-19X9-B | D41: Self Fusing Tape, Black | F41: Anixter | G41: DAS Materials | H41: 60.99 | I41: =H41*E41 -> 0 | J41: =IF(I41=0,0,I41/I$1) -> 0
A42: GPS | B42: RFS | C42: WPFG-1 | D42: Weather proofing kit (with Butyl Rubber) | F42: Anixter | G42: DAS Materials | H42: 13.31 | I42: =H42*E42 -> 0 | J42: 0.0013894606
A43: GPS | B43: ROHN | C43: FRM225 | D43: 60"H Non-Penetrating Mount TESSCO SKU: 518376 | F43: Anixter | G43: DAS Materials | H43: 191 | I43: =H43*E43 -> 0 | J43: 0.0013894606
A44: GPS | B44: ROHN | C44: FRMMAT | D44: Mat Kit for FRM Mounts, 42-1/2"x 36" x 1/8" thick. TESSCO SKU: 81998 | F44: Anixter | G44: DAS Materials | H44: 31.2 | I44: =H44*E44 -> 0 | J44: =IF(I44=0,0,I44/I$1) -> 0
A45: Rack | B45: Chatsworth | C45: 30139-719 | D45: Universal Horizontal Cable Manager; 1 RMU; 19"W ; Single-Sided; Black | F45: Anixter | G45: DAS Materials | H45: 93 | I45: =H45*E45 -> 0 | J45: =IF(I45=0,0,I45/I$1) -> 0
A46: Rack | B46: Chatsworth | C46: 30130-719 | D46: Universal Horizontal Cable Manager; 2 RMU; 19"W ; Single-Sided; Black | F46: Anixter | G46: DAS Materials | H46: 95 | I46: =H46*E46 -> 0 | J46: =IF(I46=0,0,I46/I$1) -> 0
A47: Rack | B47: Chatsworth | C47: 13698-001 | D47: Duplex Electrical Outlet Box, Zinc | F47: Anixter | G47: DAS Materials | H47: 14.5 | I47: =H47*E47 -> 0 | J47: =IF(I47=0,0,I47/I$1) -> 0
A48: Rack | B48: Chatsworth | C48: 13703-701 | D48: Floor Drilling Template, Black | F48: Anixter | G48: DAS Materials | H48: 110 | I48: =H48*E48 -> 0 | J48: =IF(I48=0,0,I48/I$1) -> 0
A49: Rack | B49: Hilti | C49: KWIK BOLT TZ2 WEDGE ANCHOR | D49: HILTI KWIK Bolt TZ, ¾” – 5 ½” L.. KWIK BOLT TZ2 WEDGE ANCHOR | F49: Anixter | G49: DAS Materials | H49: 25 | I49: =H49*E49 -> 0 | J49: =IF(I49=0,0,I49/I$1) -> 0
A50: Rack | B50: Chatsworth | C50: 32697-002 | D50: Tool-less Bend Radius Kit for Fiber Patch Cords, Pack of 50, Black | F50: Anixter | G50: DAS Materials | H50: 135 | I50: =H50*E50 -> 0 | J50: =IF(I50=0,0,I50/I$1) -> 0
A51: Rack | B51: Chatsworth | C51: 12293-X19 | D51: Heavy Duty Shelf for 6” (150 mm) Channel, For 19” Rack | F51: Anixter | G51: DAS Materials | H51: 278 | I51: =H51*E51 -> 0 | J51: =IF(I51=0,0,I51/I$1) -> 0
A52: Rack | B52: Chatsworth | C52: 12639-001 | D52: #12-24 Cage Nuts and Screws, Pack of 25, Black | F52: Anixter | G52: DAS Materials | H52: 63 | I52: =H52*E52 -> 0 | J52: =IF(I52=0,0,I52/I$1) -> 0
A53: Filter | B53: SOLiD US | C53: iBIU_AC | D53: ALLIANCE iBIU Chassis, AC Version Includes: iMCPU, iMPSU_AC | F53: Solid | G53: DAS Materials | H53: 2069.08 | I53: =H53*E53 -> 0 | J53: =IF(I53=0,0,I53/I$1) -> 0
A54: Filter | B54: SOLiD US | C54: iBIU_B | D54: ALLIANCE Input module, blank | F54: Solid | G54: DAS Materials | H54: 122 | I54: =H54*E54 -> 0 | J54: =IF(I54=0,0,I54/I$1) -> 0
...

Sheet LOE Sheet
A2: Denotes Fields for Input | C2: Denotes DO NOT TOUCH | E2: Total from Here | G2: =G113 -> 0 | I2: =I113 -> 0 | J2: =IF(I2=0,0,I2/('Labor Projections'!F9)) -> 0
A3: QTY | B3: Category | C3: Minutes Per Unit | D3: Unit | E3: Labor Type | F3: Per Hour | G3: Cost | I3: Hours | J3: Percent of Labor
A4: ~ | B4: Antenna | C4: Minutes Per Unit | D4: Unit | E4: Labor Type | F4: Per Hour | G4: =SUM(G5:G8) -> 0 | I4: =SUM(I5:I8) -> 0 | J4: =SUM(J5:J8) -> 0
B5: Adder for Hard lid ceiling | C5: 10 | D5: Each | E5: Technician | F5: =VLOOKUP(E5,'Labor Projections'!A$3:D$12,4,FALSE) -> 85 | G5: =I5*F5 -> 0 | I5: =(A5*C5)/60 -> 0 | J5: =IF(I5=0,0,I5/I$2) -> 0
B6: Install Antenna | C6: 60 | D6: Each | E6: Technician | F6: =VLOOKUP(E6,'Labor Projections'!A$3:D$12,4,FALSE) -> 85 | G6: =I6*F6 -> 0 | I6: =(A6*C6)/60 -> 0 | J6: =IF(I6=0,0,I6/I$2) -> 0
B7: Labeling Antenna | C7: 1 | D7: Each | E7: Technician | F7: =VLOOKUP(E7,'Labor Projections'!A$3:D$12,4,FALSE) -> 85 | G7: =I7*F7 -> 0 | I7: =(A7*C7)/60 -> 0 | J7: =IF(I7=0,0,I7/I$2) -> 0
B8: Develop and Install custom Antenna Mount | C8: 60 | D8: Each | E8: Technician | F8: =VLOOKUP(E8,'Labor Projections'!A$3:D$12,4,FALSE) -> 85 | G8: =I8*F8 -> 0 | I8: =(A8*C8)/60 -> 0 | J8: =IF(I8=0,0,I8/I$2) -> 0
A9: ~ | B9: Boring/Trenching/Coring | C9: Minutes Per Unit | D9: Unit | E9: Labor Type | F9: Per Hour | G9: =SUM(G10:G11) -> 0 | I9: =SUM(I10:I11) -> 0 | J9: =SUM(J10:J11) -> 0
B10: Install Pathway Sleeves in existing core | C10: 10 | D10: Each | E10: Technician | F10: =VLOOKUP(E10,'Labor Projections'!A$3:D$12,4,FALSE) -> 85 | G10: =I10*F10 -> 0 | I10: =(A10*C10)/60 -> 0 | J10: =IF(I10=0,0,I10/I$2) -> 0
B11: Drill, Sheet Rock. 6" or less | C11: 15 | D11: Each | E11: Technician | F11: =VLOOKUP(E11,'Labor Projections'!A$3:D$12,4,FALSE) -> 85 | G11: =I11*F11 -> 0 | I11: =(A11*C11)/60 -> 0 | J11: =IF(I11=0,0,I11/I$2) -> 0
A12: ~ | B12: Cable Management | C12: Minutes Per Unit | D12: Unit | E12: Labor Type | F12: Per Hour | G12: =SUM(G13:G16) -> 0 | I12: =SUM(I13:I16) -> 0 | J12: =SUM(J13:J16) -> 0
B13: Create structure to install ladder rack to | C13: 1 | D13: Per Foot | E13: Technician | F13: =VLOOKUP(E13,'Labor Projections'!A$3:D$12,4,FALSE) -> 85 | G13: =I13*F13 -> 0 | I13: =(A13*C13)/60 -> 0 | J13: =IF(I13=0,0,I13/I$2) -> 0
B14: Create structure to mount Cable tray to | C14: 1 | D14: Per Foot | E14: Technician | F14: =VLOOKUP(E14,'Labor Projections'!A$3:D$12,4,FALSE) -> 85 | G14: =I14*F14 -> 0 | I14: =(A14*C14)/60 -> 0 | J14: =IF(I14=0,0,I14/I$2) -> 0
B15: Install ladder rack to exposed structure | C15: 5 | D15: Per Foot | E15: Technician | F15: =VLOOKUP(E15,'Labor Projections'!A$3:D$12,4,FALSE) -> 85 | G15: =I15*F15 -> 0 | I15: =(A15*C15)/60 -> 0 | J15: =IF(I15=0,0,I15/I$2) -> 0
B16: Install ladder rack to structure above existing ceiling | C16: 2 | D16: Per Foot | E16: Technician | F16: =VLOOKUP(E16,'Labor Projections'!A$3:D$12,4,FALSE) -> 85 | G16: =I16*F16 -> 0 | I16: =(A16*C16)/60 -> 0 | J16: =IF(I16=0,0,I16/I$2) -> 0
A17: ~ | B17: Coax | C17: Minutes Per Unit | D17: Unit | E17: Labor Type | F17: Per Hour | G17: =SUM(G18:G33) -> 0 | I17: =SUM(I18:I33) -> 0 | J17: =SUM(J18:J33) -> 0
B18: Adder for Hard lid ceiling | C18: 4 | D18: Per Foot | E18: Technician | F18: =VLOOKUP(E18,'Labor Projections'!A$3:D$12,4,FALSE) -> 85 | G18: =I18*F18 -> 0 | I18: =(A18*C18)/60 -> 0 | J18: =IF(I18=0,0,I18/I$2) -> 0
B19: Adder driver for instances of height over 20' | C19: 4 | D19: Per Foot | E19: Technician | F19: =VLOOKUP(E19,'Labor Projections'!A$3:D$12,4,FALSE) -> 85 | G19: =I19*F19 -> 0 | I19: =(A19*C19)/60 -> 0 | J19: =IF(I19=0,0,I19/I$2) -> 0
B20: HEPA Cart and work area containment | C20: 3 | D20: Per Foot | E20: Technician | F20: =VLOOKUP(E20,'Labor Projections'!A$3:D$12,4,FALSE) -> 85 | G20: =I20*F20 -> 0 | I20: =(A20*C20)/60 -> 0 | J20: =IF(I20=0,0,I20/I$2) -> 0
B21: Connectorize captive coax up to half inch | C21: 15 | D21: Each | E21: Technician | F21: =VLOOKUP(E21,'Labor Projections'!A$3:D$12,4,FALSE) -> 85 | G21: =I21*F21 -> 0 | I21: =(A21*C21)/60 -> 0 | J21: =IF(I21=0,0,I21/I$2) -> 0
B22: Connectorize compression coax up to half inch | C22: 10 | D22: Each | E22: Technician | F22: =VLOOKUP(E22,'Labor Projections'!A$3:D$12,4,FALSE) -> 85 | G22: =I22*F22 -> 0 | I22: =(A22*C22)/60 -> 0 | J22: =IF(I22=0,0,I22/I$2) -> 0
B23: Connectorize captive coax greater than half inch | C23: 15 | D23: Each | E23: Technician | F23: =VLOOKUP(E23,'Labor Projections'!A$3:D$12,4,FALSE) -> 85 | G23: =I23*F23 -> 0 | I23: =(A23*C23)/60 -> 0 | J23: =IF(I23=0,0,I23/I$2) -> 0
B24: Connectorize compression coax greater than half inch | C24: 15 | D24: Each | E24: Technician | F24: =VLOOKUP(E24,'Labor Projections'!A$3:D$12,4,FALSE) -> 85 | G24: =I24*F24 -> 0 | I24: =(A24*C24)/60 -> 0 | J24: =IF(I24=0,0,I24/I$2) -> 0
A25: =SUM(A21:A24,A31) -> 0 | B25: Labeling Coax and Category Cable | C25: 2 | D25: Each | E25: Technician | F25: =VLOOKUP(E25,'Labor Projections'!A$3:D$12,4,FALSE) -> 85 | G25: =I25*F25 -> 0 | I25: =(A25*C25)/60 -> 0 | J25: =IF(I25=0,0,I25/I$2) -> 0
B26: Develop and Install custom mount for splitters/couplers | C26: 15 | D26: Each | E26: Technician | F26: =VLOOKUP(E26,'Labor Projections'!A$3:D$12,4,FALSE) -> 85 | G26: =I26*F26 -> 0 | I26: =(A26*C26)/60 -> 0 | J26: =IF(I26=0,0,I26/I$2) -> 0
B27: Install combiner/splitters | C27: 15 | D27: Each | E27: Technician | F27: =VLOOKUP(E27,'Labor Projections'!A$3:D$12,4,FALSE) -> 85 | G27: =I27*F27 -> 0 | I27: =(A27*C27)/60 -> 0 | J27: =IF(I27=0,0,I27/I$2) -> 0
A28: =A27*4 -> 0 | B28: Labeling for splitter | C28: 3 | D28: Each | E28: Technician | F28: =VLOOKUP(E28,'Labor Projections'!A$3:D$12,4,FALSE) -> 85 | G28: =I28*F28 -> 0 | I28: =(A28*C28)/60 -> 0 | J28: =IF(I28=0,0,I28/I$2) -> 0
B29: Adder - Painting of support, cabling, or conduit in place | C29: 1 | D29: Per Foot | E29: Technician | F29: =VLOOKUP(E29,'Labor Projections'!A$3:D$12,4,FALSE) -> 85 | G29: =I29*F29 -> 0 | I29: =(A29*C29)/60 -> 0 | J29: =IF(I29=0,0,I29/I$2) -> 0
B30: InstallCategory Cable | C30: 3 | D30: Per Foot | E30: Technician | F30: =VLOOKUP(E30,'Labor Projections'!A$3:D$12,4,FALSE) -> 85 | G30: =I30*F30 -> 0 | I30: =(A30*C30)/60 -> 0 | J30: =IF(I30=0,0,I30/I$2) -> 0
B31: Connectorize RG6/Ethernet cable | C31: 15 | D31: Each | E31: Technician | F31: =VLOOKUP(E31,'Labor Projections'!A$3:D$12,4,FALSE) -> 85 | G31: =I31*F31 -> 0 | I31: =(A31*C31)/60 -> 0 | J31: =IF(I31=0,0,I31/I$2) -> 0
A32: =A31/2 -> 0 | B32: Test Category Cable (per Drop) | C32: 15 | D32: Each | E32: Technician | F32: =VLOOKUP(E32,'Labor Projections'!A$3:D$12,4,FALSE) -> 85 | G32: =I32*F32 -> 0 | I32: =(A32*C32)/60 -> 0 | J32: =IF(I32=0,0,I32/I$2) -> 0
A33: =SUM(A21:A24)/2 -> 0 | B33: Sweep Test per line | C33: 30 | D33: Each | E33: Technician | F33: =VLOOKUP(E33,'Labor Projections'!A$3:D$12,4,FALSE) -> 85 | G33: =I33*F33 -> 0 | I33: =(A33*C33)/60 -> 0 | J33: =IF(I33=0,0,I33/I$2) -> 0
A34: ~ | B34: Conduit | C34: Minutes Per Unit | D34: Unit | E34: Labor Type | F34: Per Hour | G34: =SUM(G35:G39) -> 0 | I34: =SUM(I35:I39) -> 0 | J34: =SUM(J35:J39) -> 0
B35: Adder for Hard lid ceiling | C35: 2 | D35: Per Foot | E35: Technician | F35: =VLOOKUP(E35,'Labor Projections'!A$3:D$12,4,FALSE) -> 85 | G35: =I35*F35 -> 0 | I35: =(A35*C35)/60 -> 0 | J35: =IF(I35=0,0,I35/I$2) -> 0
B36: Adder driver for instances of height over 20' | C36: 2 | D36: Per Foot | E36: Technician | F36: =VLOOKUP(E36,'Labor Projections'!A$3:D$12,4,FALSE) -> 85 | G36: =I36*F36 -> 0 | I36: =(A36*C36)/60 -> 0 | J36: =IF(I36=0,0,I36/I$2) -> 0
B37: HEPA Cart and work area containment | C37: 2 | D37: Per Foot | E37: Technician | F37: =VLOOKUP(E37,'Labor Projections'!A$3:D$12,4,FALSE) -> 85 | G37: =I37*F37 -> 0 | I37: =(A37*C37)/60 -> 0 | J37: =IF(I37=0,0,I37/I$2) -> 0
B38: Install seal tight conduit | C38: 4 | D38: Per Foot | E38: Technician | F38: =VLOOKUP(E38,'Labor Projections'!A$3:D$12,4,FALSE) -> 85 | G38: =I38*F38 -> 0 | I38: =(A38*C38)/60 -> 0 | J38: =IF(I38=0,0,I38/I$2) -> 0
B39: Adder - Painting of support, cabling, or conduit in place | C39: 1 | D39: Per Foot | E39: Technician | F39: =VLOOKUP(E39,'Labor Projections'!A$3:D$12,4,FALSE) -> 85 | G39: =I39*F39 -> 0 | I39: =(A39*C39)/60 -> 0 | J39: =IF(I39=0,0,I39/I$2) -> 0
A40: ~ | B40: Fiber | C40: Minutes Per Unit | D40: Unit | E40: Labor Type | F40: Per Hour | G40: =SUM(G41:G49) -> 0 | I40: =SUM(I41:I49) -> 0 | J40: =SUM(J41:J49) -> 0
B41: Adder for Hard lid ceiling | C41: 4 | D41: Per Foot | E41: Technician | F41: =VLOOKUP(E41,'Labor Projections'!A$3:D$12,4,FALSE) -> 85 | G41: =I41*F41 -> 0 | I41: =(A41*C41)/60 -> 0 | J41: =IF(I41=0,0,I41/I$2) -> 0
...

Sheet Additional SOW's
A1: Denotes Fields for Input | C1: Denotes DO NOT TOUCH | E1: Total from Here | G1: =G38 -> 0 | I1: =I38 -> 0 | J1: =IF(I1=0,0,I1/('Labor Projections'!F9)) -> 0
A2: QTY | B2: Category | C2: Minutes Per Unit | D2: Unit | E2: Labor Type | F2: Per Hour | G2: Cost | I2: Hours | J2: Percent of Labor
A3: ~ | B3: Structure Support Labor | C3: Minutes /Unit /2 Labor | D3: Unit | E3: Labor Type | F3: Per Hour | G3: =SUM(G4:G7) -> 0 | I3: =SUM(I4:I7) -> 0 | J3: =SUM(J4:J7) -> 0
B4: 6x2 Ladder Rack 20'/hr | C4: 5.19 | D4: Per Foot | E4: Technician | F4: =VLOOKUP(E4,'Labor Projections'!A$3:D$12,4,FALSE) -> 85 | G4: =F4*I4 -> 0 | I4: =(A4*C4)/60 -> 0 | J4: =IF(I4=0,0,I4/I$1) -> 0
B5: 24x4 Ladder Rack 10'/hr | C5: 10.38 | D5: Per Foot | E5: Technician | F5: =VLOOKUP(E5,'Labor Projections'!A$3:D$12,4,FALSE) -> 85 | G5: =F5*I5 -> 0 | I5: =(A5*C5)/60 -> 0 | J5: =IF(I5=0,0,I5/I$1) -> 0
B6: 24x4 Wire Basket 10'/hr | C6: 10.38 | D6: Per Foot | E6: Technician | F6: =VLOOKUP(E6,'Labor Projections'!A$3:D$12,4,FALSE) -> 85 | G6: =F6*I6 -> 0 | I6: =(A6*C6)/60 -> 0 | J6: =IF(I6=0,0,I6/I$1) -> 0
B7: 1" Conduit 40'/hr -Bend/Cut | C7: 3.114 | D7: Per Foot | E7: Technician | F7: =VLOOKUP(E7,'Labor Projections'!A$3:D$12,4,FALSE) -> 85 | G7: =F7*I7 -> 0 | I7: =(A7*C7)/60 -> 0 | J7: =IF(I7=0,0,I7/I$1) -> 0
B8: 2" Conduit 20'/hr -Bend/Cut | C8: 5.709 | D8: Per Foot | E8: Technician | F8: =VLOOKUP(E8,'Labor Projections'!A$3:D$12,4,FALSE) -> 85 | G8: =F8*I8 -> 0 | I8: =(A8*C8)/60 -> 0 | J8: =IF(I8=0,0,I8/I$1) -> 0
B9: 4" Conduit 20'/hr | C9: 5.19 | D9: Per Foot | E9: Technician | F9: =VLOOKUP(E9,'Labor Projections'!A$3:D$12,4,FALSE) -> 85 | G9: =F9*I9 -> 0 | I9: =(A9*C9)/60 -> 0 | J9: =IF(I9=0,0,I9/I$1) -> 0
B10: 6" Conduit 20'/hr | C10: 5.19 | D10: Per Foot | E10: Technician | F10: =VLOOKUP(E10,'Labor Projections'!A$3:D$12,4,FALSE) -> 85 | G10: =F10*I10 -> 0 | I10: =(A10*C10)/60 -> 0 | J10: =IF(I10=0,0,I10/I$1) -> 0
A11: ~ | B11: Backbone Cabling Labor | C11: Minutes /Unit /2 Labor | D11: Unit | E11: Labor Type | F11: Per Hour | G11: =SUM(G12:G15) -> 0 | I11: =SUM(I12:I15) -> 0 | J11: =SUM(J12:J15) -> 0
B12: 25-Pair CAT3 ABAM (per ft) | C12: 2.595 | D12: Per Foot | E12: Technician | F12: =VLOOKUP(E12,'Labor Projections'!A$3:D$12,4,FALSE) -> 85 | G12: =F12*I12 -> 0 | I12: =(A12*C12)/60 -> 0 | J12: =IF(I12=0,0,I12/I$1) -> 0
B13: 12-Strand Fusion Pigtails | C13: 134.94 | D13: Per Foot | E13: Technician | F13: =VLOOKUP(E13,'Labor Projections'!A$3:D$12,4,FALSE) -> 85 | G13: =F13*I13 -> 0 | I13: =(A13*C13)/60 -> 0 | J13: =IF(I13=0,0,I13/I$1) -> 0
B14: 24-Strand Fusion Pigtails | C14: 269.88 | D14: Per Foot | E14: Technician | F14: =VLOOKUP(E14,'Labor Projections'!A$3:D$12,4,FALSE) -> 85 | G14: =F14*I14 -> 0 | I14: =(A14*C14)/60 -> 0 | J14: =IF(I14=0,0,I14/I$1) -> 0
B15: 48-Strand Fusion Pigtails | C15: 539.76 | D15: Per Foot | E15: Technician | F15: =VLOOKUP(E15,'Labor Projections'!A$3:D$12,4,FALSE) -> 85 | G15: =F15*I15 -> 0 | I15: =(A15*C15)/60 -> 0 | J15: =IF(I15=0,0,I15/I$1) -> 0
B16: Splice Trays/Cabinets | C16: 259.5 | D16: Per Foot | E16: Technician | F16: =VLOOKUP(E16,'Labor Projections'!A$3:D$12,4,FALSE) -> 85 | G16: =F16*I16 -> 0 | I16: =(A16*C16)/60 -> 0 | J16: =IF(I16=0,0,I16/I$1) -> 0
A17: ~ | B17: Demolition | C17: Minutes /Unit /2 Labor | D17: Unit | E17: Labor Type | F17: Per Hour | G17: =SUM(G18:G21) -> 0 | I17: =SUM(I18:I21) -> 0 | J17: =SUM(J18:J21) -> 0
B18: Trunk Demo <150ft | C18: 155.7 | D18: Each | E18: Technician | F18: =VLOOKUP(E18,'Labor Projections'!A$3:D$12,4,FALSE) -> 85 | G18: =F18*I18 -> 0 | I18: =(A18*C18)/60 -> 0 | J18: =IF(I18=0,0,I18/I$1) -> 0
B19: Trunk Demo >150ft | C19: 207.6 | D19: Each | E19: Technician | F19: =VLOOKUP(E19,'Labor Projections'!A$3:D$12,4,FALSE) -> 85 | G19: =F19*I19 -> 0 | I19: =(A19*C19)/60 -> 0 | J19: =IF(I19=0,0,I19/I$1) -> 0
B20: Relay Rack Demo | C20: 415.2 | D20: Each | E20: Technician | F20: =VLOOKUP(E20,'Labor Projections'!A$3:D$12,4,FALSE) -> 85 | G20: =F20*I20 -> 0 | I20: =(A20*C20)/60 -> 0 | J20: =IF(I20=0,0,I20/I$1) -> 0
C21: 0 | D21: Each | E21: Technician | F21: =VLOOKUP(E21,'Labor Projections'!A$3:D$12,4,FALSE) -> 85 | G21: =F21*I21 -> 0 | I21: =(A21*C21)/60 -> 0 | J21: =IF(I21=0,0,I21/I$1) -> 0
C22: 0 | D22: Each | E22: Technician | F22: =VLOOKUP(E22,'Labor Projections'!A$3:D$12,4,FALSE) -> 85 | G22: =F22*I22 -> 0 | I22: =(A22*C22)/60 -> 0 | J22: =IF(I22=0,0,I22/I$1) -> 0
A23: ~ | B23: Miscellaneous | C23: Minutes Per Unit | D23: Unit | E23: Labor Type | F23: Per Hour | G23: =SUM(G24:G28) -> 0 | I23: =SUM(I24:I28) -> 0 | J23: =SUM(J24:J28) -> 0
B24: Contingency | C24: 60 | D24: 0.1 | E24: Technician | F24: =VLOOKUP(E24,'Labor Projections'!A$3:D$12,4,FALSE) -> 85 | G24: =F24*I24 -> 0 | I24: =(A24*C24)/60 -> 0 | J24: =IF(I24=0,0,I24/I$1) -> 0
B25: Contingency | C25: 60 | D25: Each | E25: Construction Manager | F25: =VLOOKUP(E25,'Labor Projections'!A$3:D$12,4,FALSE) -> 95 | G25: =F25*I25 -> 0 | I25: =(A25*C25)/60 -> 0 | J25: =IF(I25=0,0,I25/I$1) -> 0
B26: A&E Site walk - KH | C26: 60 | D26: Each | E26: Construction Manager | F26: =VLOOKUP(E26,'Labor Projections'!A$3:D$12,4,FALSE) -> 95 | G26: =F26*I26 -> 0 | I26: =(A26*C26)/60 -> 0 | J26: =IF(I26=0,0,I26/I$1) -> 0
B27: Excess cable removal | C27: 60 | D27: Each | E27: Technician | F27: =VLOOKUP(E27,'Labor Projections'!A$3:D$12,4,FALSE) -> 85 | G27: =F27*I27 -> 0 | I27: =(A27*C27)/60 -> 0 | J27: =IF(I27=0,0,I27/I$1) -> 0
C28: 0 | D28: Each | E28: Technician | F28: =VLOOKUP(E28,'Labor Projections'!A$3:D$12,4,FALSE) -> 85 | G28: =F28*I28 -> 0 | I28: =(A28*C28)/60 -> 0 | J28: =IF(I28=0,0,I28/I$1) -> 0
C29: 0 | D29: Each | E29: Technician | F29: =VLOOKUP(E29,'Labor Projections'!A$3:D$12,4,FALSE) -> 85 | G29: =F29*I29 -> 0 | I29: =(A29*C29)/60 -> 0 | J29: =IF(I29=0,0,I29/I$1) -> 0
C30: 0 | D30: Each | E30: Technician | F30: =VLOOKUP(E30,'Labor Projections'!A$3:D$12,4,FALSE) -> 85 | G30: =F30*I30 -> 0 | I30: =(A30*C30)/60 -> 0 | J30: =IF(I30=0,0,I30/I$1) -> 0
C31: 0 | D31: Each | E31: Technician | F31: =VLOOKUP(E31,'Labor Projections'!A$3:D$12,4,FALSE) -> 85 | G31: =F31*I31 -> 0 | I31: =(A31*C31)/60 -> 0 | J31: =IF(I31=0,0,I31/I$1) -> 0
E32: ='Labor Projections'!A3 -> Technician | F32: Labor Total | G32: =SUMIF(E$4:G$31,E32,G$4:G$31) -> 0 | I32: =SUMIF(E$4:G$31,E32,I$4:I$31) -> 0
E33: ='Labor Projections'!A4 -> Construction Manager | F33: Labor Total | G33: =SUMIF(E$4:G$31,E33,G$4:G$31) -> 0 | I33: =SUMIF(E$4:G$31,E33,I$4:I$31) -> 0
E34: ='Labor Projections'!A5 -> RF-Engineer | F34: Labor Total | G34: =SUMIF(E$4:G$31,E34,G$4:G$31) -> 0 | I34: =SUMIF(E$4:G$31,E34,I$4:I$31) -> 0
E35: ='Labor Projections'!A6 -> RF-Technician | F35: Labor Total | G35: =SUMIF(E$4:G$31,E35,G$4:G$31) -> 0 | I35: =SUMIF(E$4:G$31,E35,I$4:I$31) -> 0
E36: ='Labor Projections'!A7 -> Project Coordinator | F36: Labor Total | G36: =SUMIF(E$4:G$31,E36,G$4:G$31) -> 0 | I36: =SUMIF(E$4:G$31,E36,I$4:I$31) -> 0
E37: ='Labor Projections'!A8 -> Project Manager | F37: Labor Total | G37: =SUMIF(E$4:G$31,E37,G$4:G$31) -> 0 | I37: =SUMIF(E$4:G$31,E37,I$4:I$31) -> 0
E38: Grand | F38: Labor Total | G38: =SUM(G32:G37) -> 0 | I38: =SUM(I32:I37) -> 0

Sheet Pass Throughs
A1: Denotes Fields for Input | D1: Denotes DO NOT TOUCH
A2: Pass Throughs | D2: Pass Throughs Grand Total | E2: =SUM(E11,E21,E31,E41,E58,E72) -> 0
A3: Per Diem
A4: Labor Type | B4: Rate | C4: Employee Count | D4: Days | E4: Total | F4: Total Days
A5: ='Labor Projections'!A$3 -> Technician | B5: 50 | D5: ='Labor Projections'!D23 -> 0 | E5: =(D5*B5)*C5 -> 0 | F5: =C5*D5 -> 0
A6: ='Labor Projections'!A$4 -> Construction Manager | B6: 50 | D6: ='Labor Projections'!D23 -> 0 | E6: =(D6*B6)*C6 -> 0 | F6: =C6*D6 -> 0
A7: ='Labor Projections'!A$5 -> RF-Engineer | B7: 50 | E7: =(D7*B7)*C7 -> 0 | F7: =C7*D7 -> 0
A8: ='Labor Projections'!A$6 -> RF-Technician | B8: 50 | E8: =(D8*B8)*C8 -> 0 | F8: =C8*D8 -> 0
A9: ='Labor Projections'!A$7 -> Project Coordinator | B9: 50 | E9: =(D9*B9)*C9 -> 0 | F9: =C9*D9 -> 0
A10: ='Labor Projections'!A$8 -> Project Manager | B10: 50 | E10: =(D10*B10)*C10 -> 0 | F10: =C10*D10 -> 0
D11: Per Diem Total | E11: =SUM(E5:E10) -> 0 | F11: =SUM(F5:F10) -> 0
A13: Lodging
A14: Labor Type | B14: Rate | C14: Employee Count | D14: Days | E14: Total | F14: Total Days
A15: ='Labor Projections'!A$3 -> Technician | B15: 120 | D15: ='Labor Projections'!D23 -> 0 | E15: =(D15*B15)*C15 -> 0 | F15: =C15*D15 -> 0
A16: ='Labor Projections'!A$4 -> Construction Manager | B16: 120 | D16: ='Labor Projections'!D23 -> 0 | E16: =(D16*B16)*C16 -> 0 | F16: =C16*D16 -> 0
A17: ='Labor Projections'!A$5 -> RF-Engineer | B17: 120 | E17: =(D17*B17)*C17 -> 0 | F17: =C17*D17 -> 0
A18: ='Labor Projections'!A$6 -> RF-Technician | B18: 120 | E18: =(D18*B18)*C18 -> 0 | F18: =C18*D18 -> 0
A19: ='Labor Projections'!A$7 -> Project Coordinator | B19: 120 | E19: =(D19*B19)*C19 -> 0 | F19: =C19*D19 -> 0
A20: ='Labor Projections'!A$8 -> Project Manager | B20: 120 | E20: =(D20*B20)*C20 -> 0 | F20: =C20*D20 -> 0
D21: Lodging Total | E21: =SUM(E15:E20) -> 0 | F21: =SUM(F15:F20) -> 0
A23: Travel
A24: Labor Type | B24: Rate | C24: Employee Count | D24: Hours | E24: Total | F24: Total Hours
A25: ='Labor Projections'!A$3 -> Technician | B25: =VLOOKUP(A25,'Labor Projections'!A3:B12,2,FALSE) -> 85 | C25: 3 | E25: =(D25*B25)*C25 -> 0 | F25: =C25*D25 -> 0
A26: ='Labor Projections'!A$4 -> Construction Manager | B26: =VLOOKUP(A26,'Labor Projections'!A4:B13,2,FALSE) -> 95 | C26: 1 | E26: =(D26*B26)*C26 -> 0 | F26: =C26*D26 -> 0
A27: ='Labor Projections'!A$5 -> RF-Engineer | B27: =VLOOKUP(A27,'Labor Projections'!A5:B14,2,FALSE) -> 75 | E27: =(D27*B27)*C27 -> 0 | F27: =C27*D27 -> 0
A28: ='Labor Projections'!A$6 -> RF-Technician | B28: =VLOOKUP(A28,'Labor Projections'!A6:B16,2,FALSE) -> 75 | E28: =(D28*B28)*C28 -> 0 | F28: =C28*D28 -> 0
A29: ='Labor Projections'!A$7 -> Project Coordinator | B29: =VLOOKUP(A29,'Labor Projections'!A7:B17,2,FALSE) -> 55 | E29: =(D29*B29)*C29 -> 0 | F29: =C29*D29 -> 0
A30: ='Labor Projections'!A$8 -> Project Manager | B30: =VLOOKUP(A30,'Labor Projections'!A8:B18,2,FALSE) -> 100 | E30: =(D30*B30)*C30 -> 0 | F30: =C30*D30 -> 0
D31: Travel Total | E31: =SUM(E25:E30) -> 0 | F31: =SUM(F25:F30) -> 0
A33: Airfare
A34: Labor Type | B34: Ticket Cost | D34: Qty | E34: Total
A35: ='Labor Projections'!A$3 -> Technician | B35: 500 | E35: =D35*B35 -> 0
A36: ='Labor Projections'!A$4 -> Construction Manager | B36: 500 | E36: =D36*B36 -> 0
A37: ='Labor Projections'!A$5 -> RF-Engineer | E37: =D37*B37 -> 0
A38: ='Labor Projections'!A$6 -> RF-Technician | E38: =D38*B38 -> 0
A39: ='Labor Projections'!A$7 -> Project Coordinator | E39: =D39*B39 -> 0
A40: ='Labor Projections'!A$8 -> Project Manager | E40: =D40*B40 -> 0
D41: Airfare Total | E41: =SUM(E35:E40) -> 0
A43: Rentals
A44: Expense Type | B44: Rate | C44: Per Qty | D44: Qty | E44: Total
...

Sheet Labor Projections
A1: Denotes Fields for Input | I1: Denotes DO NOT TOUCH
A2: Labor Type | B2: Hourly Cost | C2: Multiplier | D2: Project Hourly Cost | E2: % of project | F2: Hours | G2: Project Labor Cost | I2: Technicians Needed | J2: To Complete In days | K2: To Complete In Weeks | L2: CM's Needed | M2: Total CM Hours | N2: Total Project Hours | O2: Project Labor Estimate
A3: Technician | B3: 85 | C3: 0 | D3: =(B3*C3)+B3 -> 85 | F3: =(VLOOKUP(A3,'LOE Sheet'!E$107:I$113,5,FALSE)+VLOOKUP(A3,'Additional SOW''s'!E$32:I$38,5,FALSE))*B$18+(VLOOKUP(A3,'LOE Sheet'!E$107:I$113,5,FALSE)+VLOOKUP(A3,'Additional SOW''s'!E$32:I$38,5,FALSE)) -> 0 | G3: =F3*D3 -> 0 | I3: 20 | J3: =B$23/I3 -> 0 | K3: =B$25/I3 -> 0 | L3: 2 | M3: =B$24*L3*K3 -> 0 | N3: =B$20+M3 -> 0 | O3: =N3*B$21 -> 0
A4: Construction Manager | B4: 95 | C4: 0 | D4: =(B4*C4)+B4 -> 95 | F4: =(VLOOKUP(A4,'LOE Sheet'!E$107:I$113,5,FALSE)+VLOOKUP(A4,'Additional SOW''s'!E$32:I$38,5,FALSE))*B$18+(VLOOKUP(A4,'LOE Sheet'!E$107:I$113,5,FALSE)+VLOOKUP(A4,'Additional SOW''s'!E$32:I$38,5,FALSE)) -> 0 | G4: =F4*D4 -> 0 | I4: 19 | J4: =B$23/I4 -> 0 | K4: =B$25/I4 -> 0 | L4: 2 | M4: =B$24*L4*K4 -> 0 | N4: =B$20+M4 -> 0 | O4: =N4*B$21 -> 0
A5: RF-Engineer | B5: 75 | C5: 0 | D5: 100 | F5: =(VLOOKUP(A5,'LOE Sheet'!E$107:I$113,5,FALSE)+VLOOKUP(A5,'Additional SOW''s'!E$32:I$38,5,FALSE))*B$18+(VLOOKUP(A5,'LOE Sheet'!E$107:I$113,5,FALSE)+VLOOKUP(A5,'Additional SOW''s'!E$32:I$38,5,FALSE)) -> 0 | G5: =F5*D5 -> 0 | I5: 18 | J5: =B$23/I5 -> 0 | K5: =B$25/I5 -> 0 | L5: 2 | M5: =B$24*L5*K5 -> 0 | N5: =B$20+M5 -> 0 | O5: =N5*B$21 -> 0
A6: RF-Technician | B6: 75 | C6: 0 | D6: =(B6*C6)+B6 -> 75 | F6: =(VLOOKUP(A6,'LOE Sheet'!E$107:I$113,5,FALSE)+VLOOKUP(A6,'Additional SOW''s'!E$32:I$38,5,FALSE))*B$18+(VLOOKUP(A6,'LOE Sheet'!E$107:I$113,5,FALSE)+VLOOKUP(A6,'Additional SOW''s'!E$32:I$38,5,FALSE)) -> 0 | G6: =F6*D6 -> 0 | I6: 17 | J6: =B$23/I6 -> 0 | K6: =B$25/I6 -> 0 | L6: 2 | M6: =B$24*L6*K6 -> 0 | N6: =B$20+M6 -> 0 | O6: =N6*B$21 -> 0
A7: Project Coordinator | B7: 55 | C7: 0 | D7: =(B7*C7)+B7 -> 55 | F7: =(VLOOKUP(A7,'LOE Sheet'!E$107:I$113,5,FALSE)+VLOOKUP(A7,'Additional SOW''s'!E$32:I$38,5,FALSE))*B$18+(VLOOKUP(A7,'LOE Sheet'!E$107:I$113,5,FALSE)+VLOOKUP(A7,'Additional SOW''s'!E$32:I$38,5,FALSE)) -> 0 | G7: =F7*D7 -> 0 | I7: 16 | J7: =B$23/I7 -> 0 | K7: =B$25/I7 -> 0 | L7: 2 | M7: =B$24*L7*K7 -> 0 | N7: =B$20+M7 -> 0 | O7: =N7*B$21 -> 0
A8: Project Manager | B8: 100 | C8: 0 | D8: =(B8*C8)+B8 -> 100 | F8: =(VLOOKUP(A8,'LOE Sheet'!E$107:I$113,5,FALSE)+VLOOKUP(A8,'Additional SOW''s'!E$32:I$38,5,FALSE))*B$18+(VLOOKUP(A8,'LOE Sheet'!E$107:I$113,5,FALSE)+VLOOKUP(A8,'Additional SOW''s'!E$32:I$38,5,FALSE)) -> 0 | G8: =F8*D8 -> 0 | I8: 15 | J8: =B$23/I8 -> 0 | K8: =B$25/I8 -> 0 | L8: 2 | M8: =B$24*L8*K8 -> 0 | N8: =B$20+M8 -> 0 | O8: =N8*B$21 -> 0
D9: =G9/F9 -> #DIV/0! | F9: =SUM(F3:F8) -> 0 | G9: =SUM(G3:G8) -> 0 | I9: 14 | J9: =B$23/I9 -> 0 | K9: =B$25/I9 -> 0 | L9: 2 | M9: =B$24*L9*K9 -> 0 | N9: =B$20+M9 -> 0 | O9: =N9*B$21 -> 0
A10: Operational Admin | E10: % of Project | I10: 13 | J10: =B$23/I10 -> 0 | K10: =B$25/I10 -> 0 | L10: 2 | M10: =B$24*L10*K10 -> 0 | N10: =B$20+M10 -> 0 | O10: =N10*B$21 -> 0
A11: Construction Manager | B11: 95 | C11: 0 | D11: 95 | E11: 0.5 | F11: =IF(B26,VLOOKUP(B26,I3:M22,5,FALSE)*E11,0) -> 0 | G11: =F11*D11 -> 0 | I11: 12 | J11: =B$23/I11 -> 0 | K11: =B$25/I11 -> 0 | L11: 2 | M11: =B$24*L11*K11 -> 0 | N11: =B$20+M11 -> 0 | O11: =N11*B$21 -> 0
A12: Project Manager | B12: 100 | C12: 0 | D12: =(B12*C12)+B12 -> 100 | E12: 0.25 | F12: =IF(B26,VLOOKUP(B26,I3:M22,5,FALSE)*E12,0) -> 0 | G12: =F12*D12 -> 0 | I12: 11 | J12: =B$23/I12 -> 0 | K12: =B$25/I12 -> 0 | L12: 2 | M12: =B$24*L12*K12 -> 0 | N12: =B$20+M12 -> 0 | O12: =N12*B$21 -> 0
A13: Project Coordinator | B13: 55 | C13: 0 | D13: =(B13*C13)+B13 -> 55 | E13: 0.15 | F13: =IF(B26,VLOOKUP(B26,I3:M22,5,FALSE)*E13,0) -> 0 | G13: =F13*D13 -> 0 | I13: 10 | J13: =B$23/I13 -> 0 | K13: =B$25/I13 -> 0 | L13: 1 | M13: =B$24*L13*K13 -> 0 | N13: =B$20+M13 -> 0 | O13: =N13*B$21 -> 0
F14: =SUM(F11:F13) -> 0 | G14: =SUM(G11:G13) -> 0 | I14: 9 | J14: =B$23/I14 -> 0 | K14: =B$25/I14 -> 0 | L14: 1 | M14: =B$24*L14*K14 -> 0 | N14: =B$20+M14 -> 0 | O14: =N14*B$21 -> 0
I15: 8 | J15: =B$23/I15 -> 0 | K15: =B$25/I15 -> 0 | L15: 1 | M15: =B$24*L15*K15 -> 0 | N15: =B$20+M15 -> 0 | O15: =N15*B$21 -> 0
F16: =F14+F9 -> 0 | G16: =G14+G9 -> 0 | I16: 7 | J16: =B$23/I16 -> 0 | K16: =B$25/I16 -> 0 | L16: 1 | M16: =B$24*L16*K16 -> 0 | N16: =B$20+M16 -> 0 | O16: =N16*B$21 -> 0
A17: Hours In Project | B17: ='LOE Sheet'!I2+'Additional SOW''s'!I1 -> 0 | I17: 6 | J17: =B$23/I17 -> 0 | K17: =B$25/I17 -> 0 | L17: 1 | M17: =B$24*L17*K17 -> 0 | N17: =B$20+M17 -> 0 | O17: =N17*B$21 -> 0
A18: Staging&MaterialMultiplier | B18: 0.05 | C18: Hours | D18: =F9-B17 -> 0 | I18: 5 | J18: =B$23/I18 -> 0 | K18: =B$25/I18 -> 0 | L18: 1 | M18: =B$24*L18*K18 -> 0 | N18: =B$20+M18 -> 0 | O18: =N18*B$21 -> 0
A19: Staging& Material Time/ hour | B19: =B17*B18 -> 0 | I19: 4 | J19: =B$23/I19 -> 0 | K19: =B$25/I19 -> 0 | L19: 1 | M19: =B$24*L19*K19 -> 0 | N19: =B$20+M19 -> 0 | O19: =N19*B$21 -> 0
A20: Total Project time | B20: =B17+B19 -> 0 | I20: 3 | J20: =B$23/I20 -> 0 | K20: =B$25/I20 -> 0 | L20: 1 | M20: =B$24*L20*K20 -> 0 | N20: =B$20+M20 -> 0 | O20: =N20*B$21 -> 0
A21: Average Ops Labor Rate | B21: =IF(F9,G9/F9,0) -> 0 | I21: 2 | J21: =B$23/I21 -> 0 | K21: =B$25/I21 -> 0 | L21: 1 | M21: =B$24*L21*K21 -> 0 | N21: =B$20+M21 -> 0 | O21: =N21*B$21 -> 0
A22: Hours per Man-Day | B22: 8 | I22: 1 | J22: =B$23/I22 -> 0 | K22: =B$25/I22 -> 0 | L22: 1 | M22: =B$24*L22*K22 -> 0 | N22: =B$20+M22 -> 0 | O22: =N22*B$21 -> 0
A23: Man-Days in Project | B23: =B20/B22 -> 0 | C23: Calendar | D23: =B23/B26 -> 0 | I23: Labor Needed Guage Tool, Put Techs Needed in B25
A24: Hours per Man-Week | B24: 40
A25: Man-Weeks in Project | B25: =B20/B24 -> 0 | C25: Calendar | D25: =B25/B26 -> 0
A26: Technicians Needed | B26: 4

Sheet Drop Down Data
A1: Material | C1: Reg
A2: Equipment | C2: OT
A3: Sub | C3: DT
C5: Ungd
A6: LF | C6: Civil | E6: Ea
A7: CY | C7: Elec | E7: Lot
A8: Lot | C8: RF | E8: Each
A9: Ea | C9: Tech | E9: Week
A10: SF | E10: Month
A12: Labor | C12: Hotel | E12: Consumable
C13: Per Diem | E13: DAS Materials
A14: HR | C14: Permits | E14: BAT Materials
C15: Bond
A16: Ungd | G16: 0.5
A17: Civil | C17: Position | D17: Reg | E17: OT | F17: DT | G17: Reg Bill with MU
A18: Elec | C18: Civil - Foreman | D18: 52 | E18: 71 | F18: 89 | G18: =(D18*G$16)+D18 -> 78
A19: RF | C19: Civil - Lead | D19: 34 | E19: 49 | F19: 64 | G19: =(D19*G$16)+D19 -> 51
A20: Tech | C20: Civil - Laborer | D20: 30 | E20: 43 | F20: 57 | G20: =(D20*G$16)+D20 -> 45
A21: Supv | C21: Elec - Foreman | D21: 52 | E21: 71 | F21: 89 | G21: =(D21*G$16)+D21 -> 78
C22: Elec - Lead | D22: 34 | E22: 49 | F22: 64 | G22: =(D22*G$16)+D22 -> 51
A23: YES | C23: Elec - Laborer | D23: 30 | E23: 43 | F23: 57 | G23: =(D23*G$16)+D23 -> 45
A24: NO | C24: RF - Foreman | D24: 32 | E24: 71 | F24: 89 | G24: =(D24*G$16)+D24 -> 48
C25: RF - Lead | D25: 34 | E25: 49 | F25: 64 | G25: =(D25*G$16)+D25 -> 51
A26: Day | C26: RF - Laborer | D26: 30 | E26: 43 | F26: 57 | G26: =(D26*G$16)+D26 -> 45
A27: Week | C27: Tech - Foreman | D27: 52 | E27: 71 | F27: 89 | G27: =(D27*G$16)+D27 -> 78
A28: Month | C28: Tech - Lead | D28: 34 | E28: 49 | F28: 64 | G28: =(D28*G$16)+D28 -> 51
A29: EA | C29: Tech - Laborer | D29: 30 | E29: 43 | F29: 57 | G29: =(D29*G$16)+D29 -> 45
C30: Supervision | D30: 54 | E30: 74 | F30: 94 | G30: =(D30*G$16)+D30 -> 81
C31: Underground - Foreman | D31: 62 | E31: 87 | F31: 110 | G31: =(D31*G$16)+D31 -> 93
A32: Battery | C32: Underground - Laborer | D32: 27 | E32: 40 | F32: 52 | G32: =(D32*G$16)+D32 -> 40.5
A33: COW/COLT | C33: ACT RF - Engineer | D33: 59 | E33: 71 | F33: 89 | G33: =(D33*G$16)+D33 -> 88.5
A34: C-RAN/Dark Fiber | C34: ACT RF - Laborer | D34: 25 | E34: 35 | F34: 46 | G34: =(D34*G$16)+D34 -> 37.5
A35: DAS | C35: ACT PC | D35: 25 | E35: 35 | F35: 46 | G35: =(D35*G$16)+D35 -> 37.5
A36: DC PWR / PWR Upgrade | C36: ACT Tech - Technician | D36: 33 | E36: 47 | F36: 62 | G36: =(D36*G$16)+D36 -> 49.5
A37: Decom | C37: ACT Tech - CM | D37: 49 | E37: 67 | F37: 84 | G37: =(D37*G$16)+D37 -> 73.5
A38: Gen Mod | C38: ACT Underground - Laborer | D38: 24 | E38: 34 | F38: 44 | G38: =(D38*G$16)+D38 -> 36
A39: HVAC | C39: ACT Underground - Lead | D39: 32 | E39: 47 | F39: 61 | G39: =(D39*G$16)+D39 -> 48
A40: Microwave | C40: ACT Underground - Foreman | D40: 55 | E40: 72 | F40: 89 | G40: =(D40*G$16)+D40 -> 82.5
A41: Modification (Civil/Tower)
A42: NCD / NSD / NSB
...
